Workbook

Sheet Mode d'emploi
A1: Dossier prévisionnel pour aider à la prise de décisions : résultat et trésorerie
A2: Saisie des données
B3: Des données sont à saisir dans la feuille "hypothèses" les autres feuilles sont protégées
B4: Les instructions pour les champs à saisir sont de couleur rouge.
A6: Nature des données
B7: Les décisions sont sur fond vert. | I7: Les objectifs de ventes qui dépendent des clients autant que de
B8: Les résultats à reporter sont sur fond jaune. | I8: notre volonté sont sur fond rouge
B9: Les paramètres sont sur fond bleu.
A11: Prévisions mensuelles
B12: Pour les marges et résultats nous présentons
C13: 1. la prévision pour le mois en cours, celui pour lequel les décisions sont en préparation,
C14: 2. la prévision, pour le même mois, mais, corrigée des variations saisonnières.
B15: Pour la trésorerie la seule prévision qui présente un intérêt est la prévision pour le mois en cours.
A17: Limites du dossier
B18: Il n'intègre pas les stratégies de commercialisation par négociation directe dans les onglets "Marges" et "Résultats", seule est envisagée
B19: la vente sur le marché concurrentiel.

Sheet hypothèses
B1: Différentes hypothèses pour les prévisions du mois à venir.
B2: Saisir les coûts HT des matières consommées G12 et H12 | J2: Saisir les charges récurrentes du trimestre écoulé et du trimestre à venir
B3: Modifier éventuellement les consommations G15 àI18 | J3: Renseigner les champs relatifs aux investissements
B4: Saisir les décisions commerciales G21 à J24 | J4: Renseigner les champs relatifs aux financement
B5: Saisir les coefficients saisonniers du mois à venir G26 à I26
B7: Les champs qui ne nécessitent pas de saisie sont protégés
C8: Numéro du dernier mois écoulé | F8: 0
B10: ACTIVITE | L10: INVESTISSEMENT
C11: Approvisionnement. | G11: Plastique | H11: Bois | L11: Nombre de machines au début du mois
D12: Coûts unitaires HT (par tonne et par m3) | G12: 5200 | H12: 2150 | M12: Moulage | O12: 5
M13: Finition | O13: 6
C14: Production. | G14: Pech4 | H14: Prom5.5 | I14: Stan8 | L14: Acquisitions | N14: Q | O14: CU | P14: Total invest | Q14: Cu HTM
D15: Consommation plastique par bateau (t) | G15: 0.2 | H15: 0.4 | I15: 1 | M15: Moulage | N15: 0 | O15: 100000 | P15: =N15*O15 -> 0 | Q15: 50
D16: Consommation bois par bateau (en m3) | G16: 0.1 | H16: 0.2 | I16: 0.5 | M16: Finition | N16: 0 | O16: 100000 | P16: =N16*O16 -> 0 | Q16: 70
D17: Consommation moulage (en HTM) | G17: 8 | H17: 12 | I17: 28 | L17: Cessions | N17: Q | O17: CU | P17: Total cess
D18: Consommation finition (en HTM) | G18: 10 | H18: 14 | I18: 28 | M18: Moulage | N18: 0 | O18: 25000 | P18: =N18*O18 -> 0
M19: Finition | N19: 0 | O19: 25000 | P19: =N19*O19 -> 0
C20: Commercialisation. | G20: Pech4 | H20: Prom5.5 | I20: Stan8 | J20: Commun
D21: Objectifs mensuels de ventes | G21: 42 | H21: 35 | I21: 4
D22: Prix unitaires HT prévus | G22: 6000 | H22: 10000 | I22: 30000
D23: Taux de commission représentants | J23: 0.03
D24: Publicités spécifiques et marque prévues | G24: 1500 | H24: 1500 | I24: 5000 | J24: 20000
D25: Coefficients saisonniers du mois en
D26: cours | G26: 0.7 | H26: 0.5 | I26: 0.4
C28: Charges fixes récurrentes mensuelles | G28: Mois | I28: Mois | L28: FINANCEMENT
G29: à venir | I29: écoulé
B30: Charges externes fixes | L30: Finance.
C31: Consommables | G31: 10000 | I31: 10000 | L31: Montant | M31: Capitaux propres | P31: 2863989.8
C32: Achats fournitures | G32: 12000 | I32: 12000 | L32: Flux | M32: Emprunts | P32: 0
C33: Déplacements, missions, réceptions | G33: 8000 | I33: 8000 | M33: Retraits placements | P33: 0
C34: Frais postaux et télécommunications | G34: 500 | I34: 500 | M34: Remboursements | P34: 0
C35: Maintenance, entretien machines | G35: 25000 | I35: 25000 | M35: Placements | P35: 0
C36: Redevance crédit bail | G36: 0 | I36: 0
C37: Etudes de marché | G37: 500 | I37: 0 | L37: BFR | P37: Mois à venir | Q37: Mois écoulé
C38: Assurances (y compris emprunts) | G38: 2700 | I38: 2700 | M38: Montants des stocks fin du mois | P38: 316068.15 | Q38: 316068.15
C39: Frais bancaires | G39: 0 | I39: 0 | M39: Créances clients fin du mois | P39: 1087200 | Q39: 1087200
B40: Impôts et taxes | G40: 5629 | I40: 5629 | M40: TVA déductible fin du mois | P40: 93357 | Q40: 93357
B41: Salaires bruts (hors commissions) | G41: 85400 | I41: 85400 | M41: Dettes fournisseurs fin du mois | P41: 230418 | Q41: 230418
B42: Charges sociales (hors charges sur commissions) | G42: 42700 | I42: 42700 | M42: TVA collectée fin du mois | P42: 181200 | Q42: 181200
B43: Dotations aux amortissements | G43: 21250 | I43: 21250 | M43: Impôts sur les bénéfices | P43: 431930 | Q43: 431930
...

Sheet Synthèse des résultats
B50: Pech4 | C50: Prom5.5 | D50: Stan8
A51: Taux de MSCV | B51: =100*Marges!$E$17 -> 51.25 | C51: =100*Marges!$H$17 -> 49.6 | D51: =100*Marges!$K$17 -> 58.383333
B52: Pech4 | C52: Prom5.5 | D52: Stan8
A53: Marge contribution | B53: =Marges!$E$27/1000 -> 183 | C53: =Marges!$H$27/1000 -> 345.7 | D53: =Marges!$K$27/1000 -> 170.15

Sheet Marges
B2: Prévision des marges sur coûts variables et marges de contributionensuelles.
B3: Ne rien saisir
C4: Pech4 | F4: Prom5.5 | I4: Stan8 | L4: Total
B5: Prix de vente HT | E5: =hypothèses!G22 -> 6000 | H5: =hypothèses!H22 -> 10000 | K5: =hypothèses!I22 -> 30000 | L5: =(E5*E20)+(H20*H5)+(K20*K5) -> 1360000
B7: Représentants | C7: taux comm | D7: =hypothèses!J23 -> 0.03 | E7: =E5*$D$7 -> 180 | H7: =H5*$D$7 -> 300 | K7: =K5*$D$7 -> 900
B8: Consommation de matières
B9: Plastique | C9: =hypothèses!G15 -> 0.2 | D9: =hypothèses!G12 -> 5200 | E9: =C9*D9 -> 1040 | F9: =hypothèses!H15 -> 0.4 | G9: =D9 -> 5200 | H9: =F9*G9 -> 2080 | I9: =hypothèses!I15 -> 1 | J9: =D9 -> 5200 | K9: =I9*J9 -> 5200
B10: Bois | C10: =hypothèses!G16 -> 0.1 | D10: =hypothèses!H12 -> 2150 | E10: =C10*D10 -> 215 | F10: =hypothèses!H16 -> 0.2 | G10: =D10 -> 2150 | H10: =F10*G10 -> 430 | I10: =hypothèses!I16 -> 0.5 | J10: =D10 -> 2150 | K10: =I10*J10 -> 1075
B11: Consommation de temps
B12: Moulage | C12: =hypothèses!G17 -> 8 | D12: =hypothèses!Q15 -> 50 | E12: =C12*D12 -> 400 | F12: =hypothèses!H17 -> 12 | G12: =D12 -> 50 | H12: =F12*G12 -> 600 | I12: =hypothèses!I17 -> 28 | J12: =D12 -> 50 | K12: =I12*J12 -> 1400
B13: Finition | C13: =hypothèses!G18 -> 10 | D13: =hypothèses!Q16 -> 70 | E13: =C13*D13 -> 700 | F13: =hypothèses!H18 -> 14 | G13: =D13 -> 70 | H13: =F13*G13 -> 980 | I13: =hypothèses!I18 -> 28 | J13: =D13 -> 70 | K13: =I13*J13 -> 1960
B14: CV services extérieurs | D14: 0.065 | E14: =D14*E5 -> 390 | G14: 0.065 | H14: =G14*H5 -> 650 | J14: 0.065 | K14: =J14*K5 -> 1950
B15: M S C V unitaires | E15: =E5-SUM(E7:E14) -> 3075 | H15: =H5-SUM(H7:H14) -> 4960 | K15: =K5-SUM(K7:K14) -> 17515 | L15: =E20*E15+H20*H15+K20*K15 -> 706850 | M15: MSCV | N15: =+E17 -> 0.5125 | O15: =+H17 -> 0.496 | P15: =K17 -> 0.58383333
B17: Taux de marge sur C V | E17: =E15/E5 -> 0.5125 | H17: =H15/H5 -> 0.496 | K17: =K15/K5 -> 0.58383333 | L17: =L15/L5 -> 0.51974265
D18: Attendu | E18: Corrigé | G18: Attendu | H18: Corrigé | J18: Attendu | K18: Corrigé
B20: Objectif mensuel de ventes | D20: =hypothèses!G21 -> 42 | E20: =D20/hypothèses!G26 -> 60 | G20: =hypothèses!H21 -> 35 | H20: =G20/hypothèses!H26 -> 70 | J20: =hypothèses!I21 -> 4 | K20: =J20/hypothèses!I26 -> 10
B22: M S C V par type de bateaux | D22: =D20*E15 -> 129150 | E22: =E15*E20 -> 184500 | G22: =G20*H15 -> 173600 | H22: =H15*H20 -> 347200 | J22: =J20*K15 -> 70060 | K22: =K15*K20 -> 175150
B24: Coûts fixes spécifiques mensuels
B25: Publicité spécifique | D25: =E25 -> 1500 | E25: =hypothèses!G24 -> 1500 | G25: =H25 -> 1500 | H25: =hypothèses!H24 -> 1500 | J25: =K25 -> 5000 | K25: =hypothèses!I24 -> 5000
M26: Marges | N26: =E27 -> 183000 | O26: =H27 -> 345700 | P26: =K27 -> 170150
B27: M. de contribution corrigée | E27: =E22-E25 -> 183000 | H27: =H22-H25 -> 345700 | K27: =K22-K25 -> 170150 | L27: =E27+H27+K27 -> 698850
B28: M. de contribution attendue | D28: =D22-D25 -> 127650 | G28: =G22-G25 -> 172100 | J28: =J22-J25 -> 65060 | L28: =SUM(C28:K28) -> 364810

Sheet Résultat
B2: Résultat prévisionnel du mois à venir | J2: Résultat du mois corrigé des variations saisonnières
E3: Pech4 | F3: Prom5.5 | G3: Stan8 | H3: Total | N3: Pech4 | O3: Prom5.5 | P3: Stan8 | Q3: Total
K4: Rappel des coefficients saisonniers | N4: =hypothèses!G26 -> 0.7 | O4: =hypothèses!H26 -> 0.5 | P4: =hypothèses!I26 -> 0.4
B5: Marge sur coûts variables | E5: =Marges!D22 -> 129150 | F5: =Marges!G22 -> 173600 | G5: =Marges!J22 -> 70060 | H5: =SUM(E5:G5) -> 372810 | K5: Marge sur coûts variables | N5: =E5/hypothèses!G26 -> 184500 | O5: =F5/hypothèses!H26 -> 347200 | P5: =G5/hypothèses!I26 -> 175150 | Q5: =SUM(N5:P5) -> 706850
B6: Publicité spécifique | E6: =Marges!E25 -> 1500 | F6: =Marges!H25 -> 1500 | G6: =Marges!K25 -> 5000 | H6: =SUM(E6:G6) -> 8000 | K6: Publicité spécifique | N6: =E6 -> 1500 | O6: =F6 -> 1500 | P6: =G6 -> 5000 | Q6: =H6 -> 8000
B7: Marge de contribution | E7: =E5-E6 -> 127650 | F7: =F5-F6 -> 172100 | G7: =G5-G6 -> 65060 | H7: =SUM(E7:G7) -> 364810 | K7: Marge de contribution | N7: =N5-N6 -> 183000 | O7: =O5-O6 -> 345700 | P7: =P5-P6 -> 170150 | Q7: =Q5-Q6 -> 698850
B9: Charges fixes hors publicité | H9: =hypothèses!G46 -> 218929 | K9: Charges fixes hors publicité | Q9: =H9 -> 218929
B10: Publicité de marque | H10: =hypothèses!J24 -> 20000 | K10: Publicité de marque mensuelle | Q10: =H10 -> 20000
B11: Résultat | H11: =H7-H9-H10 -> 125881 | K11: Résultat mensuel | Q11: =Q7-Q9-Q10 -> 459921
B13: Taux de profitabilité (corrigé des variations saisonnières) | K13: Taux de rentabilité des capitaux propres sur une année
F14: Résultat | G14: Ch. d'affaires | H14: Taux | O14: Résultat | P14: Cap.propres | Q14: Taux
B15: Rapport du résultat sur le chiffre d'affaires | F15: =Q11 -> 459921 | G15: =Marges!L5 -> 1360000 | H15: =F15/G15 -> 0.33817721 | K15: Rapport du résultat sur le chiffre d'affaires | O15: =Q11*12 -> 5519052 | P15: =hypothèses!P31 -> 2863989.8 | Q15: =O15/P15 -> 1.9270502

Sheet Flux trésorerie
A2: Ne rien saisir | C2: Prévision des flux de trésorerie du mois à venir.
C5: Flux liés à l'activité.
E6: Résultat | G6: =Résultat!H11 -> 125881 | J6: Cash flow
E7: Dotations / amortissements | G7: =hypothèses!G43 -> 21250
E8: Variation BFR | G8: =hypothèses!Q45-hypothèses!P45 -> 0 | I8: L'accroissement du BFR est retranché du cash flow
E9: Total I | G9: =SUM(G6:G8) -> 147131 | I9: La diminution du BFR est ajoutée au Cash flow
C10: Flux liés aux investissements
E11: Acquisitions | G11: =-(hypothèses!N15*hypothèses!O15+hypothèses!N16*hypothèses!O16) -> 0
E12: Cessions | G12: =hypothèses!N18*hypothèses!O18+hypothèses!N19*hypothèses!O19 -> 0
E13: Total II | G13: =SUM(G11:G12) -> 0
C14: Flux liés au financements
E15: Encaissements | G15: =hypothèses!P32+hypothèses!P33 -> 0
E16: Décaissements | G16: =-(hypothèses!P34+hypothèses!P35) -> 0
E17: Total III | G17: =SUM(G15:G16) -> 0
C19: Flux nets de trésorerie du trimestre | G19: =G9+G13+G17 -> 147131
C21: Solde de trésorerie début du mois | G21: =hypothèses!Q46 -> 111233.19
C22: Solde de trésorerie fin de mois | G22: =G21+G19 -> 258364.19
